<mujoco model="pendulum">

    <compiler inertiafromgeom="true" angle="radian" coordinate="local" />
    <option timestep="0.01" gravity="0 0 -1" iterations="20" integrator="Euler" />
  <default>
    <joint armature='0.04' damping="0.1" limited="false"/>
    <geom contype="2" conaffinity="1" condim="1" friction=".5 .1 .1" density="1000" margin="0.002" />
  </default>

    <worldbody>
        <body name="link1" pos="0 0 0">
            <site name="end_effector" pos="0 0 1" size="0.01" />
            <geom name="link1" type="capsule" fromto="0 0 0 0 0 1" size="0.05" />
            <joint name="joint1" type="hinge" pos="0 0 0" axis="0 1 0" />
        </body>
        <site name="target" pos="0 0 1" size="0.01" />
    </worldbody>

    <actuator>
        <motor joint="joint1" />
    </actuator>
</mujoco>
